Workbook
Name CIQWBGuid: "e778162b-a8f3-4f2e-935f-34d73fb7e972"
Name CIQWBGuid: "eeeac8b3-2cb4-40c8-a5e7-67bd1e29d27d"
Name CIQWBInfo: "{ ""CIQVersion"":""9.51.3510.3078"" }"
Name CurrentPrice: Cover!$G$19
Name Gross_Profit: '[1]Advanced Financial Analysis'!$9:$9
Name IFF_Price: Cover!$G$19
Name IQ_CH: 110000
Name IQ_CQ: 5000
Name IQ_CY: 10000
Name IQ_DAILY: 500000
Name IQ_DNTM: 700000
Name IQ_FH: 100000
Name IQ_FQ: 500
Name IQ_FWD_CY: 10001
Name IQ_FWD_CY1: 10002
Name IQ_FWD_CY2: 10003
Name IQ_FWD_FY: 1001
Name IQ_FWD_FY1: 1002
Name IQ_FWD_FY2: 1003
Name IQ_FWD_Q: 501
Name IQ_FWD_Q1: 502
Name IQ_FWD_Q2: 503
Name IQ_FY: 1000
Name IQ_LATESTK: 1000
Name IQ_LATESTQ: 500
Name IQ_LTM: 2000
Name IQ_LTMMONTH: 120000
Name IQ_MONTH: 15000
Name IQ_MTD: 800000
Name IQ_NAMES_REVISION_DATE_: 45318.8008796296
Name IQ_NTM: 6000
Name IQ_QTD: 750000
Name IQ_TODAY: 0
Name IQ_WEEK: 50000
Name IQ_YTD: 3000
Name IQ_YTDMONTH: 130000
Name Sensitivity: '[1]Advanced Financial Analysis'!$D$49
Name SG_A: '[1]Advanced Financial Analysis'!$11:$11
Name TargetCurrentPrice: Comps!$E$18
Name TargetDilutedShares: Comps!$F$18

Sheet Cover
A1: eb
D11: FSLR - CamSIF Michaelmas
D13: Industrials
D14: CamSIF
D17: Date | G17: =+TODAY() -> 45982
D19: Share Price | E19: 45976 | G19: 245.84
L20: Case Legend
D21: OpCase | G21: 3 | J21: 1 | L21: 1 | M21: Base
J22: 2 | L22: =L21+1 -> 2 | M22: Bull
D23: Case Upside | F23: =DCF!V25 -> 148.4385 | G23: =(DCF!V25-CurrentPrice)/CurrentPrice -> -0.39619875 | J23: 3 | L23: =L22+1 -> 3 | M23: Bear
D25: Base Case | G25: 359.12
D27: Base Upside | G27: =(G25-CurrentPrice)/CurrentPrice -> 0.4607875

Sheet Assumptions
C2: First Solar
C3: Assumptions
C4: Active Case: | D4: 3
C6: $ In Millions, Unless Otherwise Noted
F7: Historical Years | I7: Forecasted Years | P7: Comments
F8: 2021A | G8: 2022A | H8: 2023A | I8: 2024A | J8: 2025E | K8: 2026E | L8: 2027E | M8: 2028E
C10: Products Revenue | F10: ='Three Statement Model'!D32 -> 2932.4 | G10: ='Three Statement Model'!E32 -> 2619.3 | H10: ='Three Statement Model'!F32 -> 3318.6 | I10: =4206.3 -> 4206.3 | J10: =J13*J19 -> 5467.878 | K10: =K13*K19 -> 7108.2414 | L10: =L13*L19 -> 9240.7138 | M10: =M13*M19 -> 12012.928
C11: % Growth | G11: =(G10-F10)/F10 -> -0.10677261 | H11: =(H10-G10)/G10 -> 0.26697973 | I11: =(I10-H10)/H10 -> 0.26749232 | J11: =(J10-I10)/I10 -> 0.29992583 | K11: =(K10-J10)/J10 -> 0.3 | L11: =(L10-K10)/K10 -> 0.3 | M11: =(M10-L10)/L10 -> 0.3
C13: Modules Sold Per year | F13: 7900 | G13: 9100 | H13: 12100 | I13: =15578 -> 15578 | J13: =+I13*(1+J14) -> 20251.4 | K13: =+J13*(1+K14) -> 26326.82 | L13: =+K13*(1+L14) -> 34224.866 | M13: =+L13*(1+M14) -> 44492.326
C14: % Growth | G14: =(G13/F13)-1 -> 0.15189873 | H14: =(H13/G13)-1 -> 0.32967033 | I14: =(I13/H13)-1 -> 0.28743802 | J14: =+OFFSET(J14,$D$4,) -> 0.3 | K14: =+OFFSET(K14,$D$4,) -> 0.3 | L14: =+OFFSET(L14,$D$4,) -> 0.3 | M14: =+OFFSET(M14,$D$4,) -> 0.3
C15: Base | J15: 0.35 | K15: 0.35 | L15: 0.35 | M15: 0.35
C16: Bull | J16: 0.38 | K16: 0.38 | L16: 0.38 | M16: 0.38
C17: Bear | J17: 0.3 | K17: 0.3 | L17: 0.3 | M17: 0.3
P18: Modules sold per year is based on the GW figures in the 10-Q. E.g. 2024A was 23.6GW of solar modules. Revenue per model sold is the Revenue/Gwatt. Per module on ASP
C19: Revenue Per Module Sold | F19: =F10/F13 -> 0.37118987 | G19: =G10/G13 -> 0.28783516 | H19: =H10/H13 -> 0.27426446 | I19: =I10/I13 -> 0.27001541 | J19: =J20 -> 0.27 | K19: =K20 -> 0.27 | L19: =L20 -> 0.27 | M19: =M20 -> 0.27
C20: % Growth | G20: =(G19-F19)/F19 -> -0.22456084 | H20: =(H19-G19)/G19 -> -0.047147478 | J20: =+OFFSET(J20,$D$4,) -> 0.27 | K20: =+OFFSET(K20,$D$4,) -> 0.27 | L20: =+OFFSET(L20,$D$4,) -> 0.27 | M20: =+OFFSET(M20,$D$4,) -> 0.27
C21: Base | J21: 0.3 | K21: 0.3 | L21: 0.3 | M21: 0.3
C22: Bull | J22: 0.32 | K22: 0.3 | L22: 0.3 | M22: 0.3
C23: Bear | J23: 0.27 | K23: 0.27 | L23: 0.27 | M23: 0.27
C25: Cost of Goods Sold | F25: 2193.4 | G25: 2491.7 | H25: 2017.9 | I25: =I10*(I26) -> 1880.37 | J25: =J10*(J26) -> 3280.7268 | K25: =K10*(K26) -> 4264.9448 | L25: =L10*(L26) -> 5544.4283 | M25: =M10*(M26) -> 7207.7568
C26: % of Products Revenue | F26: =F25/F10 -> 0.747988 | G26: =G25/G10 -> 0.95128469 | H26: =H25/H10 -> 0.60805761 | I26: ='Three Statement Model'!G33/'Three Statement Model'!G32*-1 -> 0.44703659 | J26: =+OFFSET(J26,$D$4,) -> 0.6 | K26: =+OFFSET(K26,$D$4,) -> 0.6 | L26: =+OFFSET(L26,$D$4,) -> 0.6 | M26: =+OFFSET(M26,$D$4,) -> 0.6
C27: Base | J27: 0.5 | K27: 0.5 | L27: 0.5 | M27: 0.5
C28: Bull | J28: 0.5 | K28: 0.5 | L28: 0.48 | M28: 0.45
C29: Bear | J29: 0.6 | K29: 0.6 | L29: 0.6 | M29: 0.6
C31: SG&A Expense | I31: =I32*(I10) -> 378.567 | J31: =J32*(J10) -> 492.10902 | K31: =K32*(K10) -> 639.74173 | L31: =L32*(L10) -> 831.66424 | M31: =M32*(M10) -> 1081.1635
C32: % of Revenue | F32: =F31/(F19+F10) -> 0 | G32: =G31/(G19+G10) -> 0 | H32: =H31/(H19+H10) -> 0 | I32: =+OFFSET(I32,$D$4,) -> 0.09 | J32: =+OFFSET(J32,$D$4,) -> 0.09 | K32: =+OFFSET(K32,$D$4,) -> 0.09 | L32: =+OFFSET(L32,$D$4,) -> 0.09 | M32: =+OFFSET(M32,$D$4,) -> 0.09
C33: Base | I33: 0.07 | J33: 0.07 | K33: 0.07 | L33: 0.07 | M33: 0.07
C34: Bull | I34: 0.06 | J34: 0.06 | K34: 0.06 | L34: 0.06 | M34: 0.06
C35: Bear | I35: 0.09 | J35: 0.09 | K35: 0.09 | L35: 0.09 | M35: 0.09
C37: R&D Expense | I37: =I38*(I10) -> 164.0457 | J37: =J38*(J10) -> 213.24724 | K37: =K38*(K10) -> 277.22141 | L37: =L38*(L10) -> 360.38784 | M37: =M38*(M10) -> 468.50419
C38: % of Revenue | F38: =F37/(F19+F10) -> 0 | G38: =G37/(G19+G10) -> 0 | H38: =H37/(H19+H10) -> 0 | I38: =+OFFSET(I38,$D$4,) -> 0.039 | J38: =+OFFSET(J38,$D$4,) -> 0.039 | K38: =+OFFSET(K38,$D$4,) -> 0.039 | L38: =+OFFSET(L38,$D$4,) -> 0.039 | M38: =+OFFSET(M38,$D$4,) -> 0.039
C39: Base | I39: 0.035 | J39: 0.035 | K39: 0.035 | L39: 0.035 | M39: 0.035
C40: Bull | I40: 0.035 | J40: 0.035 | K40: 0.035 | L40: 0.035 | M40: 0.035
C41: Bear | I41: 0.039 | J41: 0.039 | K41: 0.039 | L41: 0.039 | M41: 0.039
C43: Depreciation & Amort | F43: 243.6 | G43: 253.3 | H43: 292 | I43: =I44*I10 -> 504.756 | J43: =J44*J10 -> 656.14536 | K43: =K44*K10 -> 852.98897 | L43: =L44*L10 -> 1108.8857 | M43: =M44*M10 -> 1441.5514
C44: % of Revenue | G44: =G43/(G19+G10) -> 0.096694601 | H44: =H43/(H19+H10) -> 0.08798164 | I44: =+OFFSET(I44,$D$4,) -> 0.12 | J44: =+OFFSET(J44,$D$4,) -> 0.12 | K44: =+OFFSET(K44,$D$4,) -> 0.12 | L44: =+OFFSET(L44,$D$4,) -> 0.12 | M44: =+OFFSET(M44,$D$4,) -> 0.12
C45: Base | I45: 0.08 | J45: 0.08 | K45: 0.08 | L45: 0.08 | M45: 0.08
C46: Bull | I46: 0.06 | J46: 0.06 | K46: 0.06 | L46: 0.06 | M46: 0.06
C47: Bear | I47: 0.12 | J47: 0.12 | K47: 0.12 | L47: 0.12 | M47: 0.12
C49: Other Operating Expense | I49: =I50*I10 -> 84.126 | J49: =J50*J10 -> 109.35756 | K49: =K50*K10 -> 142.16483 | L49: =L50*L10 -> 184.81428 | M49: =M50*M10 -> 240.25856
...

Sheet Metrics & Drivers
B2: Metrics & Drivers | G2: Case
B3: $ in millions, unless otherwise noted | G3: =Cover!$G$21 -> 3
B5: For Fiscal Year Ending | F5: 2021 | G5: =F5+1 -> 2022 | H5: =G5+1 -> 2023 | I5: =H5+1 -> 2024 | J5: =I5+1 -> 2025 | K5: =J5+1 -> 2026 | L5: =K5+1 -> 2027 | M5: =L5+1 -> 2028
A7: x | B7: Revenue Build
B9: Revenue
B10: % of revenue | I10: =OFFSET(I37,$G$3,0)
B11: Base
B12: Bull
B13: Bear
B15: Modules Sold per year
B16: % Growth | I16: =OFFSET(I37,$G$3,0)
B17: Base
B18: Bull
B19: Bear
A34: x | B34: Other Metrics & Drivers
B36: Cost of Goods Sold
B37: % of revenue | I37: =OFFSET(I37,$G$3,0)
B38: Base
B39: Bull
B40: Bear
B42: SG&A Expense
B43: % of revenue
B44: Base
B45: Bull
B46: Bear
B48: D&A Expense
B49: % of capex
B50: Base
B51: Bull
... B130: Bear

Sheet Additional Schedules
B2: Additional Schedules
B3: $ in millions, unless otherwise noted
B5: For Fiscal Year Ending | F5: 2021 | G5: =F5+1 -> 2022 | H5: =G5+1 -> 2023 | I5: =H5+1 -> 2024 | J5: =I5+1 -> 2025 | K5: =J5+1 -> 2026 | L5: =K5+1 -> 2027 | M5: =L5+1 -> 2028
B7: Net Working Capital
B9: Current Operating Asset 1
B10: Current Operating Asset 2
B11: Current Operating Asset 3
B12: Current Operating Asset 4
B13: Total Current Operating Assets
B15: Current Operating Liability 1
B16: Current Operating Liability 2
B17: Current Operating Liability 3
B18: Current Operating Liability 4
B19: Total Current Operating Liabilities
B21: Net Working Capital
B22: Change in Net Working Capital

Sheet Three Statement Model
B5: Assumptions & Drivers
B7: All figures in USD Millions unless stated | D7: 2021A | E7: 2022A | F7: 2023A | G7: 2024A | H7: 2025E | I7: 2026E | J7: 2027E | K7: 2028E
B9: Days in Period | D9: 365 | E9: 365 | F9: 365 | G9: =365+1 -> 366 | H9: 365 | I9: 365 | J9: 365 | K9: =365+1 -> 366
B11: Income Statement
B12: Sales Growth | E12: =E32/D32-1 -> -0.10677261 | F12: =F32/E32-1 -> 0.26697973 | G12: =G32/F32-1 -> 0.26749232 | H12: =Assumptions!J11 -> 0.29992583 | I12: =Assumptions!K11 -> 0.3 | J12: =Assumptions!L11 -> 0.3 | K12: =Assumptions!M11 -> 0.3
B13: Gross Margin | D13: =D34/D32 -> 0.38731756 | E13: =E34/E32 -> 0.23204673 | F13: =F34/F32 -> 0.4861086 | G13: =G34/G32 -> 0.55296341 | H13: =(1-Assumptions!J26) -> 0.4 | I13: =(1-Assumptions!K26) -> 0.4 | J13: =(1-Assumptions!L26) -> 0.4 | K13: =(1-Assumptions!M26) -> 0.4
B14: SG&A | D14: =D36 -> 170.3 | E14: =E36 -> 164.7 | F14: =F36 -> 197.6 | G14: =G36 -> 188.3 | H14: =G14*(1+Assumptions!J32) -> 205.247 | I14: =H14*(1+Assumptions!K32) -> 223.71923 | J14: =I14*(1+Assumptions!L32) -> 243.85396 | K14: =J14*(1+Assumptions!M32) -> 265.80082
B15: Research Expense (Percent of Sales) | D15: =D37/D32 -> 0.033794844 | E15: =E37/E32 -> 0.043064941 | F15: =F37/F32 -> 0.045892846 | G15: =G37/G32 -> 0.045503174 | H15: =Assumptions!I38 -> 0.039 | I15: =Assumptions!J38 -> 0.039 | J15: =Assumptions!K38 -> 0.039 | K15: =Assumptions!L38 -> 0.039
B16: Capital Expenditure % of Revenue | D16: =D118/D32*-1 -> 0.18425181 | E16: =E118/E32*-1 -> 0.34497767 | F16: =F118/F32*-1 -> 0.41773639 | G16: =G118/G32*-1 -> 0.36278915 | H16: =Assumptions!J86 -> 0.28 | I16: =Assumptions!K86 -> 0.2 | J16: =Assumptions!L86 -> 0.15 | K16: =Assumptions!M86 -> 0.0802 | L16: Converges to D&A
B17: Interest Expense % of Revenue | D17: =D44/D32 -> -0.0044673305 | E17: =E44/E32 -> -0.004657733 | F17: =F44/F32 -> -0.0039173145 | G17: =G44/G32 -> -0.0092480327 | H17: =Assumptions!I109*-1 -> -0.012 | I17: =Assumptions!J109*-1 -> -0.012 | J17: =Assumptions!K109*-1 -> -0.012 | K17: =Assumptions!L109*-1 -> -0.012
B18: Depreciation (Percent of Sales) | D18: =D106/D32 -> 0.083071887 | E18: =E106/E32 -> 0.096705227 | F18: =F106/F32 -> 0.087988911 | G18: =G106/G32 -> 0.09680717 | H18: =Assumptions!I44 -> 0.12 | I18: =Assumptions!J44 -> 0.12 | J18: =Assumptions!K44 -> 0.12 | K18: =Assumptions!L44 -> 0.12
B19: Tax Rate (Percent of EBT) | D19: =D50/D48*-1 -> -0.18087986 | E19: - | F19: =F50/F48*-1 -> -0.067942863 | G19: =G50/G48*-1 -> -0.081296481 | H19: =Assumptions!J91*-1 -> -0.09 | I19: =Assumptions!K91*-1 -> -0.12 | J19: =Assumptions!L91*-1 -> -0.18 | K19: =Assumptions!M91*-1 -> -0.21
B21: Balance Sheet
B22: Capital Asset Turnover Ratio | C22: (x) | D22: =D32/D71 -> 0.95381213 | E22: =E32/E71 -> 0.72155037 | F22: =F32/F71 -> 0.73766338 | G22: =G32/G71 -> 0.75690995 | H22: =AVERAGE($E22:G22) -> 0.7387079 | I22: =AVERAGE($E22:H22) -> 0.7387079 | J22: =AVERAGE($E22:I22) -> 0.7387079 | K22: =AVERAGE($E22:J22) -> 0.7387079
B23: Receivable Days (Sales Basis) | C23: (Days) | D23: =D62/D32*D9 -> 59.086584 | E23: =E62/E32*E9 -> 45.191272 | F23: =F62/F32*F9 -> 72.67884 | G23: =G62/G32*G9 -> 109.79217 | H23: =Assumptions!I62 -> 55 | I23: =Assumptions!J62 -> 55 | J23: =Assumptions!K62 -> 55 | K23: =Assumptions!L62 -> 55
B24: Inventory Days (COGS Basis) | C24: (Days) | D24: =D63/-D33*D9 -> 158.13829 | E24: =E63/-E33*E9 -> 133.51578 | F24: =F63/-F33*F9 -> 207.1986 | G24: =G63/-G33*G9 -> 252.76281 | H24: =AVERAGE($E24:G24) -> 197.82573 | I24: =AVERAGE($E24:H24) -> 197.82573 | J24: =AVERAGE($E24:I24) -> 197.82573 | K24: =AVERAGE($E24:J24) -> 197.82573
B25: Payable Days (COGS Basis) | C25: (Days) | D25: =D77/-D33*D9 -> 39.270467 | E25: =E77/-E33*E9 -> 61.949292 | F25: =F77/-F33*F9 -> 44.346194 | G25: =G77/-G33*G9 -> 93.856635 | H25: =Assumptions!I80 -> 35 | I25: =Assumptions!J80 -> 35 | J25: =Assumptions!K80 -> 35 | K25: =Assumptions!L80 -> 35
B26: Long Term Debt | D26: =D85 -> 236 | E26: =E85 -> 184.3 | F26: =F85 -> 464.1 | G26: =G85 -> 373.3 | H26: =AVERAGE($E26:G26) -> 340.56667 | I26: =AVERAGE($E26:H26) -> 340.56667 | J26: =AVERAGE($E26:I26) -> 340.56667 | K26: =AVERAGE($E26:J26) -> 340.56667
B28: Income Statement
B30: All figures in USD Millions unless stated | D30: =D$7 -> 2021A | E30: =E$7 -> 2022A | F30: =F$7 -> 2023A | G30: =G$7 -> 2024A | H30: =H$7 -> 2025E | I30: =I$7 -> 2026E | J30: =J$7 -> 2027E | K30: =K$7 -> 2028E
B32: Total Revenue | D32: 2932.4 | E32: 2619.3 | F32: 3318.6 | G32: 4206.3 | H32: =Assumptions!J10 -> 5467.878 | I32: =H32*(1+I12) -> 7108.2414 | J32: =I32*(1+J12) -> 9240.7138 | K32: =J32*(1+K12) -> 12012.928
B33: Cost Of Goods Sold | D33: =-2040.23+D38 -> -1796.63 | E33: =-2264.8+E38 -> -2011.5 | F33: =-1997.4+F38 -> -1705.4 | G33: =-2287.57+G38 -> -1880.37 | H33: =(1-H13)*H32*-1 -> -3280.7268 | I33: =(1-I13)*I32*-1 -> -4264.9448 | J33: =(1-J13)*J32*-1 -> -5544.4283 | K33: =(1-K13)*K32*-1 -> -7207.7568
B34: Gross Profit | D34: =SUM(D32,D33) -> 1135.77 | E34: =SUM(E32,E33) -> 607.8 | F34: =SUM(F32,F33) -> 1613.2 | G34: =SUM(G32,G33) -> 2325.93 | H34: =SUM(H32,H33) -> 2187.1512 | I34: =SUM(I32,I33) -> 2843.2966 | J34: =SUM(J32,J33) -> 3696.2855 | K34: =SUM(K32,K33) -> 4805.1712
B36: Selling General & Admin Exp. | D36: 170.3 | E36: 164.7 | F36: 197.6 | G36: 188.3 | H36: =H14 -> 205.247 | I36: =I14 -> 223.71923 | J36: =J14 -> 243.85396 | K36: =K14 -> 265.80082
B37: R & D Exp. | D37: 99.1 | E37: 112.8 | F37: 152.3 | G37: 191.4 | H37: =H15*H32 -> 213.24724 | I37: =I15*I32 -> 277.22141 | J37: =J15*J32 -> 360.38784 | K37: =K15*K32 -> 468.50419
B38: Depreciation & Amort. | D38: 243.6 | E38: 253.3 | F38: 292 | G38: 407.2 | H38: =-H149 -> 666.864 | I38: =-I149 -> 770.56102 | J38: =-J149 -> 848.69149 | K38: =-K149 -> 913.18136
B39: Other Operating Expenses | D39: 21.1 | E39: 73 | F39: 64.7 | G39: 84.5 | H39: =G33*Assumptions!I97*-1 -> 169.2333 | I39: =H33*Assumptions!J97*-1 -> 295.26541 | J39: =I33*Assumptions!K97*-1 -> 383.84504 | K39: =J33*Assumptions!L97*-1 -> 498.99855
B40: Total Operating Expenses | D40: =SUM(D36:D39) -> 534.1 | E40: =SUM(E36:E39) -> 603.8 | F40: =SUM(F36:F39) -> 706.6 | G40: =SUM(G36:G39) -> 871.4 | H40: =SUM(H36:H39) -> 1254.5915 | I40: =SUM(I36:I39) -> 1566.7671 | J40: =SUM(J36:J39) -> 1836.7783 | K40: =SUM(K36:K39) -> 2146.4849
B42: EBIT (Operating Income) | D42: =D34-D40 -> 601.67 | E42: =E34-E40 -> 4 | F42: =F34-F40 -> 906.6 | G42: =G34-G40 -> 1454.53 | H42: =H34-H40 -> 932.55966 | I42: =I34-I40 -> 1276.5295 | J42: =J34-J40 -> 1859.5072 | K42: =K34-K40 -> 2658.6863
B44: Interest Expense | D44: -13.1 | E44: -12.2 | F44: -13 | G44: -38.9 | H44: =H17*G85 -> -4.4796 | I44: =I17*H85 -> -3.39 | J44: =J17*I85 -> -2.3004 | K44: =K17*J85 -> -1.2108
B45: Interest and Invest. Income | D45: 0.033 | E45: 33.2 | F45: 19.09 | G45: 17.586 | H45: =G45 -> 17.586 | I45: =H45 -> 17.586 | J45: =I45 -> 17.586 | K45: =J45 -> 17.586 | L45: Flatline
B46: Foreign Currency Loss | D46: -16.4 | E46: -16.4 | F46: -21.5 | G46: =F46/F32*G32 -> -27.251085 | H46: =G46/G32*H32 -> -35.424389 | I46: =H46/H32*I32 -> -46.051706 | J46: =I46/I32*J32 -> -59.867217 | K46: =J46/J32*K32 -> -77.827382 | L46: %Revenue
B47: Net Interest Exp. | D47: =SUM(D44:D46) -> -29.467 | E47: =SUM(E44:E46) -> 4.6 | F47: =SUM(F44:F46) -> -15.41 | G47: =SUM(G44:G46) -> -48.565085 | H47: =SUM(H44:H46) -> -22.317989 | I47: =SUM(I44:I46) -> -31.855706 | J47: =SUM(J44:J46) -> -44.581617 | K47: =SUM(K44:K46) -> -61.452182
B48: Earnings Before Taxes | D48: =D42+D47 -> 572.203 | E48: =E42+E47 -> 8.6 | F48: =F42+F47 -> 891.19 | G48: =G42+G47 -> 1405.9649 | H48: =H42+H47 -> 910.24167 | I48: =I42+I47 -> 1244.6738 | J48: =J42+J47 -> 1814.9256 | K48: =K42+K47 -> 2597.2341
B50: Taxes | D50: 103.5 | E50: 52.8 | F50: 60.55 | G50: 114.3 | H50: =H32*H19*-1 -> 492.10902 | I50: =I32*I19*-1 -> 852.98897 | J50: =J32*J19*-1 -> 1663.3285 | K50: =K32*K19*-1 -> 2522.7149
B51: Net Income | D51: =D48-D50 -> 468.703 | E51: =E48-E50 -> -44.2 | F51: =F48-F50 -> 830.64 | G51: =G48-G50 -> 1291.6649 | H51: =H48-H50 -> 418.13265 | I51: =I48-I50 -> 391.68481 | J51: =J48-J50 -> 151.5971 | K51: =K48-K50 -> 74.519215
B53: Dividends | D53: 0 | E53: 0 | F53: 0 | G53: 0 | H53: =G53 -> 0 | I53: =H53 -> 0 | J53: =I53 -> 0 | K53: =J53 -> 0
B55: Balance Sheet
B57: All figures in USD Millions unless stated | D57: =D$7 -> 2021A | E57: =E$7 -> 2022A | F57: =F$7 -> 2023A | G57: =G$7 -> 2024A | H57: =H$7 -> 2025E | I57: =I$7 -> 2026E | J57: =J$7 -> 2027E | K57: =K$7 -> 2028E
B59: Assets
...

Sheet DCF
B2: Discounted Cash Flow Analysis
B3: $ in millions, unless otherwise noted | F3: =TODAY() -> 45982
B5: For Fiscal Year Ending | G5: 2025 | H5: =G5+1 -> 2026 | I5: =H5+1 -> 2027 | J5: =I5+1 -> 2028 | N5: Exit Multiple Method | S5: Perpetuity Growth Method
B7: Total Revenues | G7: ='Three Statement Model'!H32 -> 5467.878 | H7: ='Three Statement Model'!I32 -> 7108.2414 | I7: ='Three Statement Model'!J32 -> 9240.7138 | J7: ='Three Statement Model'!K32 -> 12012.928 | N7: =$J$5&"E Adjusted EBITDA" -> 2028E Adjusted EBITDA | Q7: =J18+J16 -> 3571.8676 | S7: =$J$5&"E Unlevered Free Cash Flow" -> 2028E Unlevered Free Cash Flow | V7: =J30 -> 660.6619 | X7: change (after you adjust your new schedule to include more years)
B8: % growth | H8: =(H7-G7)/G7 -> 0.3 | I8: =(I7-H7)/H7 -> 0.3 | J8: =(J7-I7)/I7 -> 0.3 | N8: Terminal Multiple | Q8: 9 | S8: Perpetuity Growth Rate | V8: 0.025
N9: Terminal Value | Q9: =Q8*Q7 -> 32146.809 | S9: Terminal Value | V9: =(V7*(1+V8))/(D33-V8) -> 7213.359 | Y9: Terminal Value = (2028 Cash Flow *(1 + PGR))/(WACC - PGR)
B10: Cost of Goods Sold | G10: ='Three Statement Model'!H33*-1 -> 3280.7268 | H10: ='Three Statement Model'!I33*-1 -> 4264.9448 | I10: ='Three Statement Model'!J33*-1 -> 5544.4283 | J10: ='Three Statement Model'!K33*-1 -> 7207.7568 | N10: Discount Factor | Q10: =J35 -> 0.63807022 | S10: Discount Factor | V10: =J35 -> 0.63807022 | Y10: Note that you can use this formula to solve for the "implied multiple"
B11: Gross Profit | G11: =G7-G10 -> 2187.1512 | H11: =H7-H10 -> 2843.2966 | I11: =I7-I10 -> 3696.2855 | J11: =J7-J10 -> 4805.1712 | N11: Present Value of Terminal Value | Q11: =Q10*Q9 -> 20511.921 | S11: Present Value of Terminal Value | V11: =V10*V9 -> 4602.6296 | Y11: Because Terminal Value is also Exit Multiple * Adj. EBITDA
B12: % margin | G12: =G11/G7 -> 0.4 | H12: =H11/H7 -> 0.4 | I12: =I11/I7 -> 0.4 | J12: =J11/J7 -> 0.4 | N12: Present Value of Cash Flow | Q12: =J38 -> 468.0633 | S12: Present Value of Cash Flow | V12: =J38 -> 468.0633 | Y12: So Implied Multiple = Terminal Value / Adj. EBITDA
N13: Total Enterprise Value | Q13: =SUM(Q11:Q12) -> 20979.984 | S13: Total Enterprise Value | V13: =V12+V11 -> 5070.6929 | Y13: Implied PGR is a bit more complicated, have to algebraically solve for PGR, kind of a pain
B14: SG&A Expense | G14: ='Three Statement Model'!H36 -> 205.247 | H14: ='Three Statement Model'!I36 -> 223.71923 | I14: ='Three Statement Model'!J36 -> 243.85396 | J14: ='Three Statement Model'!K36 -> 265.80082 | N14: Implied PGR | Q14: =((Q9*D33)-(V7))/(Q9+V7) -> 0.096346915 | S14: Implied Terminal Multiple | V14: =V9/Q7 -> 2.0194923
B15: R&D Expense | G15: ='Three Statement Model'!H37 -> 213.24724 | H15: ='Three Statement Model'!I37 -> 277.22141 | I15: ='Three Statement Model'!J37 -> 360.38784 | J15: ='Three Statement Model'!K37 -> 468.50419 | N15: Less: Debt | Q15: 891.9 | S15: Less: Debt | V15: 891.9 | Y15: Implied PGR = ((Terminal Value * WACC) - (2028 Cash Flow))/(Terminal Value + 2028 Cash Flow)
B16: D&A Expense | G16: ='Three Statement Model'!H38 -> 666.864 | H16: ='Three Statement Model'!I38 -> 770.56102 | I16: ='Three Statement Model'!J38 -> 848.69149 | J16: ='Three Statement Model'!K38 -> 913.18136 | N16: Plus: Cash | Q16: 2039.9 | S16: Plus: Cash | V16: 2039.9 | Y16: Note: Delete this text above when done
B17: Other Operating Expense | G17: ='Three Statement Model'!H39 -> 169.2333 | H17: ='Three Statement Model'!I39 -> 295.26541 | I17: ='Three Statement Model'!J39 -> 383.84504 | J17: ='Three Statement Model'!K39 -> 498.99855 | N17: Total Equity Value | Q17: =Q16+Q15+Q13 -> 23911.784 | S17: Total Equity Value | V17: =V16+V15+V13 -> 8002.4929
B18: EBIT | G18: =G11-SUM(G14:G17) -> 932.55966 | H18: =H11-SUM(H14:H17) -> 1276.5295 | I18: =I11-SUM(I14:I17) -> 1859.5072 | J18: =J11-SUM(J14:J17) -> 2658.6863 | N18: Diluted Shares Outstanding (2025) | Q18: 107.5 | S18: Diluted Shares Outstanding | V18: 107.5 | Y18: PGR actual is 3.5% given GDP is 3.8%
B19: % margin | G19: =G18/G7 -> 0.17055239 | H19: =H18/H7 -> 0.17958443 | I19: =I18/I7 -> 0.20122982 | J19: =J18/J7 -> 0.22131876 | N19: Implied Share Price | Q19: =Q17/Q18 -> 222.4352 | S19: Implied Share Price | V19: =V17/V18 -> 74.441794
N20: Upside / (Downside) | Q20: =(Q19-CurrentPrice)/CurrentPrice -> -0.095203366 | S20: Upside / (Downside) | V20: =(V19-CurrentPrice)/CurrentPrice -> -0.69719413
B21: Taxes | G21: ='Three Statement Model'!H50 -> 492.10902 | H21: ='Three Statement Model'!I50 -> 852.98897 | I21: ='Three Statement Model'!J50 -> 1663.3285 | J21: ='Three Statement Model'!K50 -> 2522.7149
B22: % effective tax rate | G22: =G21/G7 -> 0.09 | H22: =H21/H7 -> 0.12 | I22: =I21/I7 -> 0.18 | J22: =J21/J7 -> 0.21 | N22: Blended Implied Share Price
B23: Net Operating Profit After Tax | G23: =G18-G21 -> 440.45064 | H23: =H18-H21 -> 423.54051 | I23: =I18-I21 -> 196.17871 | J23: =J18-J21 -> 135.9714 | N23: Exit Multiple Method | V23: 0.5
B24: % margin | G24: =G23/G7 -> 0.080552389 | H24: =H23/H7 -> 0.05958443 | I24: =I23/I7 -> 0.021229822 | J24: =J23/J7 -> 0.011318756 | N24: Perpetuity Growth Method | V24: 0.5
N25: Blended Implied Share Price | V25: =Q19*V23+V19*V24 -> 148.4385
B26: Plus: D&A Expense | G26: =G16 -> 666.864 | H26: =H16 -> 770.56102 | I26: =I16 -> 848.69149 | J26: =J16 -> 913.18136
B27: Less: Capital Expenditures | G27: ='Three Statement Model'!H118*-1 -> 1531.0058 | H27: ='Three Statement Model'!I118*-1 -> 1421.6483 | I27: ='Three Statement Model'!J118*-1 -> 1386.1071 | J27: ='Three Statement Model'!K118*-1 -> 963.43682
B28: Less: Change in Net Working Capital | G28: =SUM('Three Statement Model'!H108:H113)*-1 -> 276.48796 | H28: =SUM('Three Statement Model'!I108:I113)*-1 -> 349.44694 | I28: =SUM('Three Statement Model'!J108:J113)*-1 -> 454.28102 | J28: =SUM('Three Statement Model'!K108:K113)*-1 -> 574.94597
B29: Less: Stub Period
B30: Unlevered Free Cash Flow | G30: =G23+G26-G27+G28 -> -147.20324 | H30: =H23+H26-H27+H28 -> 121.9002 | I30: =I23+I26-I27+I28 -> 113.04416 | J30: =J23+J26-J27+J28 -> 660.6619
B31: % margin | G31: =G30/G7 -> -0.026921457 | H31: =H30/H7 -> 0.017149136 | I31: =I30/I7 -> 0.012233271 | J31: =J30/J7 -> 0.05499591
B33: WACC | D33: =WACC!$J$23 -> 0.11887838 | G33: =$D$33 -> 0.11887838 | H33: =$D$33 -> 0.11887838 | I33: =$D$33 -> 0.11887838 | J33: =$D$33 -> 0.11887838
B34: Discount Period | G34: =F34+1 -> 1 | H34: =G34+1 -> 2 | I34: =H34+1 -> 3 | J34: =I34+1 -> 4
B35: Discount Factor | G35: =1/(1+G33)^G34 -> 0.89375219 | H35: =1/(1+H33)^H34 -> 0.79879297 | I35: =1/(1+I33)^I34 -> 0.71392297 | J35: =1/(1+J33)^J34 -> 0.63807022
B36: Present Value of Unlevered Free Cash Flow | G36: =G30*G35 -> -131.56322 | H36: =H30*H35 -> 97.373021 | I36: =I30*I35 -> 80.704819 | J36: =J30*J35 -> 421.54868
B38: Sum of Present Value Cash Flows | J38: =SUM(G36:J36) -> 468.0633
B41: DCF Sensitivity Analysis: Upside / (Downside) - Exit Multiple Method
D42: Exit Multiple
C43: =Q17/Q18 -> 222.4352 | D43: 8.2 | E43: 8.7 | F43: 9.2 | G43: 9.7 | H43: 10.2 | I43: 10.7 | J43: 11.2
B44: WACC | C44: 0.077 | D44: 234.89433 | E44: 247.24226 | F44: 259.59018 | G44: 271.93811 | H44: 284.28604 | I44: 296.63397 | J44: 308.9819
C45: 0.082 | D45: 231.07841 | E45: 243.19967 | F45: 255.32094 | G45: 267.4422 | H45: 279.56346 | I45: 291.68472 | J45: 303.80599
C46: 0.087 | D46: 227.3496 | E46: 239.24937 | F46: 251.14915 | G46: 263.04892 | H46: 274.94869 | I46: 286.84847 | J46: 298.74824
C47: =WACC!$J$23 -> 0.11887838 | D47: 205.47444 | E47: 216.07492 | F47: 226.6754 | G47: 237.27587 | H47: 247.87635 | I47: 258.47682 | J47: 269.0773
...

Sheet WACC
B2: Weighted Average Cost of Capital
B3: $ in millions, unless otherwise noted
B5: Inputs | G5: Cost of Debt Calculation
B6: Risk-Free Rate | E6: 0.0415
B7: Equity Risk Premium | E7: 0.05 | G7: Risk-Free Rate | J7: 0.0415
B8: Beta | E8: =J17 -> 1.59 | G8: Credit Spread on [XXX] Rating
B9: Effective Tax Rate | E9: =J10 -> 0.2557 | G9: Pre-Tax Cost of Debt | J9: 4.47
B10: Current Share Price | E10: =CurrentPrice -> 245.84 | G10: Effective Tax Rate (US Corp Tax 2025) | J10: 0.2557
B11: Diluted Shares Outstanding | E11: 107300000 | G11: After-Tax Cost of Debt | J11: =J9*(1+J10)/100 -> 0.05612979
B12: Market Value of Debt | E12: 891900000
G13: Cost of Equity Calculation
G15: Risk-Free Rate | J15: =J7 -> 0.0415
G16: Equity Risk Premium | J16: 0.05
E17: 16/11/2025 | G17: Beta | J17: 1.59
G18: Cost of Equity | J18: =J15+J16*J17 -> 0.121
B20: Weighted Average Cost of Capital Calculation | G20: Total Value | I20: % | J20: Cost
B21: Market Value of Debt | G21: =E12 -> 891900000 | I21: =G21/G23 -> 0.032705633 | J21: =J11 -> 0.05612979
B22: Market Value of Equity | G22: =E10*E11 -> 26378632000 | I22: =G22/G23 -> 0.96729437 | J22: =J18 -> 0.121
B23: Total | G23: =SUM(G21:G22) -> 27270532000 | I23: =SUM(I21:I22) -> 1 | J23: =I21*J21+I22*J22 -> 0.11887838

Sheet Comps
B2: Comparable Companies Analysis | F2: Date
B3: $ in millions, unless otherwise noted | F3: =TODAY() -> 45982
B5: Valuation Metrics
B6: Company Name | C6: Day Close Price Latest | D6: Shares Outstanding Latest | E6: Market Capitalization Latest | F6: LTM Net Debt | G6: Total Enterprise Value Latest | H6: LTM Total Revenue | I6: LTM EBITDA | J6: LTM EBIT | K6: EV / Revenue | L6: EV / EBIT | M6: NTM Forward PE (CapIQ)
B7: Canadian Solar Inc. (NasdaqGS:CSIQ) | C7: 28.47 | D7: 67 | E7: 1906.1 | F7: 4889.9 | G7: 8286.8 | H7: 5899.1 | I7: 656.7 | J7: 99 | K7: =G7/H7 -> 1.4047567 | L7: =G7/J7 -> 83.705051 | M7: NM
B8: Sunrun Inc. (NasdaqGS:RUN) | C8: 18.57 | D8: 232 | E8: 4309 | F8: 14021.7 | G8: 19991.4 | H8: 2316.7 | I8: 345.9 | J8: -357.6 | K8: =G8/H8 -> 8.6292571 | L8: =G8/J8 -> -55.904362 | M8: 30.47
B9: JinkoSolar Holding Co., Ltd. (NYSE:JKS) | C9: 30.58 | D9: 51.7 | E9: 1579.5 | F9: 2561.4 | G9: 5965.7 | H9: 9657.6 | I9: 106.9 | J9: -936.1 | K9: =G9/H9 -> 0.61772076 | L9: =G9/J9 -> -6.3729302 | M9: 22.02x
B10: JA Solar Technology Co., Ltd. (SZSE:002459) | C10: 1.95 | D10: 3267.3 | E10: 6376.1 | F10: 3138 | G10: 9529.8 | H10: 7398.1 | I10: 422 | J10: -644.5 | K10: =G10/H10 -> 1.2881415 | L10: =G10/J10 -> -14.786346 | M10: 86.36x
B11: LONGi Green Energy Technology Co., Ltd. (SHSE:601012) | C11: 2.98 | D11: 7557.9 | E11: 22490.2 | F11: -2707.8 | G11: 19847.7 | H11: 10538.7 | I11: -366.9 | J11: -1409.7 | K11: =G11/H11 -> 1.8833158 | L11: =G11/J11 -> -14.079379 | M11: NM
B12: Trina Solar Co., Ltd. (SHSE:688599) | C12: 2.92 | D12: 2160.7 | E12: 6301.9 | F12: 3919.3 | G12: 10970.4 | H12: 9441.4 | I12: 24.8 | J12: -993.7 | K12: =G12/H12 -> 1.1619463 | L12: =G12/J12 -> -11.039952 | M12: NM
B13: Enphase Energy, Inc. (NasdaqGM:ENPH) | C13: 27.53 | D13: 130.9 | E13: 3602.6 | F13: -244.3 | G13: 3358.3 | H13: 1512.4 | I13: 281.4 | J13: 207.1 | K13: =G13/H13 -> 2.2205104 | L13: =G13/J13 -> 16.215838 | M13: 13.40x
B14: Skyworks Solutions, Inc. (NasdaqGS:SWKS) | C14: 63.16 | D14: 148.7 | E14: 9390.6 | F14: -185.3 | G14: 9205.3 | H14: 4086.9 | I14: 974.7 | J14: 511.7 | K14: =G14/H14 -> 2.2523918 | L14: =G14/J14 -> 17.989642 | M14: 14.35x
B15: Sanan Optoelectronics Co.,Ltd (SHSE:600703) | C15: 1.89 | D15: 4867.6 | E15: 9197.6 | F15: 603.9 | G15: 9811.9 | H15: 2542.1 | I15: 538.1 | J15: -0.3 | K15: =G15/H15 -> 3.8597616 | L15: - | M15: 136.21x
B16: ON Semiconductor Corporation (NasdaqGS:ON) | C16: 46.02 | D16: 402.4 | E16: 18517.5 | F16: 760.3 | G16: 19298.5 | H16: 6187.8 | I16: 1859 | J16: 1221.3 | K16: =G16/H16 -> 3.1187983 | L16: =G16/J16 -> 15.801605 | M16: 17.02x | O16: ASP advanced solar power
B18: First Solar, Inc. | C18: 253.54 | D18: 107.3 | E18: 27206.9 | F18: -1148 | G18: 26058.9 | H18: 5050.6 | I18: 2018.7 | J18: 1505.7 | K18: =G18/H18 -> 5.1595652 | L18: =G18/J18 -> 17.306834 | M18: 11.56
B20: Minimum | C20: =MIN(C7:C18) -> 1.89 | D20: =MIN(D7:D18) -> 51.7 | E20: =MIN(E7:E18) -> 1579.5 | F20: =MIN(F7:F18) -> -2707.8 | G20: =MIN(G7:G18) -> 3358.3 | H20: =MIN(H7:H18) -> 1512.4 | I20: =MIN(I7:I18) -> -366.9 | J20: =MIN(J7:J18) -> -1409.7 | ... M20: =MIN(M7:M18) -> 11.56
B21: 25th Percentile | C21: =_xlfn.PERCENTILE.INC(C7:C18,0.25) -> 2.95 | D21: =_xlfn.PERCENTILE.INC(D7:D18,0.25) -> 119.1 | E21: =_xlfn.PERCENTILE.INC(E7:E18,0.25) -> 3955.8 | F21: =_xlfn.PERCENTILE.INC(F7:F18,0.25) -> -214.8 | G21: =_xlfn.PERCENTILE.INC(G7:G18,0.25) -> 8746.05 | H21: =_xlfn.PERCENTILE.INC(H7:H18,0.25) -> 3314.5 | I21: =_xlfn.PERCENTILE.INC(I7:I18,0.25) -> 194.15 | J21: =_xlfn.PERCENTILE.INC(J7:J18,0.25) -> -790.3 | ... M21: =_xlfn.PERCENTILE.INC(M7:M18,0.25) -> 16.2875
B22: Mean | C22: =AVERAGE(C7:C18) -> 43.419091 | D22: =AVERAGE(D7:D18) -> 1726.6818 | E22: =AVERAGE(E7:E18) -> 10079.818 | F22: =AVERAGE(F7:F18) -> 2328.1 | G22: =AVERAGE(G7:G18) -> 12938.609 | H22: =AVERAGE(H7:H18) -> 5875.5818 | I22: =AVERAGE(I7:I18) -> 623.75455 | J22: =AVERAGE(J7:J18) -> -72.463636 | ... M22: =AVERAGE(M7:M18) -> 21.015
B23: Median | C23: =MEDIAN(C7:C18) -> 27.53 | D23: =MEDIAN(D7:D18) -> 232 | E23: =MEDIAN(E7:E18) -> 6376.1 | F23: =MEDIAN(F7:F18) -> 760.3 | G23: =MEDIAN(G7:G18) -> 9811.9 | H23: =MEDIAN(H7:H18) -> 5899.1 | I23: =MEDIAN(I7:I18) -> 422 | J23: =MEDIAN(J7:J18) -> -0.3 | ... M23: =MEDIAN(M7:M18) -> 21.015
B24: 75th Percentile | C24: =_xlfn.PERCENTILE.INC(C7:C18,0.75) -> 38.3 | D24: =_xlfn.PERCENTILE.INC(D7:D18,0.75) -> 2714 | E24: =_xlfn.PERCENTILE.INC(E7:E18,0.75) -> 13954.05 | F24: =_xlfn.PERCENTILE.INC(F7:F18,0.75) -> 3528.65 | G24: =_xlfn.PERCENTILE.INC(G7:G18,0.75) -> 19573.1 | H24: =_xlfn.PERCENTILE.INC(H7:H18,0.75) -> 8419.75 | I24: =_xlfn.PERCENTILE.INC(I7:I18,0.75) -> 815.7 | J24: =_xlfn.PERCENTILE.INC(J7:J18,0.75) -> 359.4 | ... M24: =_xlfn.PERCENTILE.INC(M7:M18,0.75) -> 25.7425
B25: Maximum | C25: =MAX(C7:C18) -> 253.54 | D25: =MAX(D7:D18) -> 7557.9 | E25: =MAX(E7:E18) -> 27206.9 | F25: =MAX(F7:F18) -> 14021.7 | G25: =MAX(G7:G18) -> 26058.9 | H25: =MAX(H7:H18) -> 10538.7 | I25: =MAX(I7:I18) -> 2018.7 | J25: =MAX(J7:J18) -> 1505.7 | ... M25: =MAX(M7:M18) -> 30.47 | O25: =13.03*M25 -> 397.0241

Sheet FIELD
C3: Open | D3: Low | E3: High | F3: Close
B4: 52 wk avg (2025) | C4: 116.56 | D4: 116.56 | E4: 281.55 | F4: 281.55 | G4: =AVERAGE(F4,D4) -> 199.055
B5: Blended share price | C5: 134.72 | D5: 134.72 | E5: 457.79 | F5: 457.79 | G5: =AVERAGE(F5,D5) -> 296.255
B6: Perpetuity growth DCF | C6: 83 | D6: 83 | E6: 385.22 | F6: 385.22 | G6: =AVERAGE(F6,D6) -> 234.11
B7: Exit multiple DCF | C7: 208.72 | D7: 208.72 | E7: 530.36 | F7: 530.36 | G7: =AVERAGE(F7,D7) -> 369.54
B8: Comps | C8: 253.54 | D8: 253.54 | E8: 397.02 | F8: 397.02 | G8: =AVERAGE(F8,D8) -> 325.28 | H8: =MEDIAN(G5:G8) -> 310.7675 | I8: =MEDIAN(G6:G8) -> 325.28 | J8: =MEDIAN(G7:G8) -> 347.41

Sheet Case Comparison
C3: Open | D3: Low | E3: High | F3: Close | H3: Median | I3: Median excl. public market | J3: Median DCF
B4: 52 wk avg (2025) | C4: 116.56 | D4: 116.56 | E4: 281.55 | F4: 281.55 | G4: =AVERAGE(F4,D4) -> 199.055
B5: Blended share price | C5: 134.72 | D5: 134.72 | E5: 457.79 | F5: 457.79 | G5: =AVERAGE(F5,D5) -> 296.255
B6: Perpetuity growth DCF | D6: 74.405444 | E6: 384.37381 | G6: =MEDIAN(D6:E6) -> 229.38963 | L6: =AVERAGE(D6:E6) -> 229.38963
B7: Exit multiple DCF | D7: 222.39459 | E7: 530.02303 | G7: =MEDIAN(D7:E7) -> 376.20881 | L7: =AVERAGE(D7:E7) -> 376.20881 | M7: =AVERAGE(L6:L7) -> 302.79922
B8: Comps | C8: 253.54 | D8: 253.54 | E8: 397.02 | F8: 397.02 | G8: =AVERAGE(F8,D8) -> 325.28 | H8: =MEDIAN(G5:G8) -> 310.7675 | I8: =MEDIAN(G6:G8) -> 325.28 | J8: =MEDIAN(G6:G7) -> 302.79922 | M8: 245
M9: =M7/M8-1 -> 0.23591518
B44: Revenue Growth | C44: 2021A | D44: 2022A | E44: 2023A | F44: 2024A | G44: 2025E | H44: 2026E | I44: 2027E | J44: 2028E
B45: Base Case | C45: 2932.4 | D45: 2619.3 | E45: 3318.6 | F45: 4673.4 | G45: 6309.09 | H45: 8517.2715 | I45: 11498.317 | J45: 15522.727
B46: Bull Case | C46: 2932.4 | D46: 2619.3 | E46: 3318.6 | F46: 4984.96 | G46: 6879.2448 | H46: 8900.023 | I46: 12282.032 | J46: 16949.204
B47: Bear Case | C47: 2932.4 | D47: 2619.3 | E47: 3318.6 | F47: 4206.06 | G47: 5467.878 | H47: 7108.2414 | I47: 9240.7138 | J47: 12012.928
B57: Capex | C57: 2021A | D57: 2022A | E57: 2023A | F57: 2024A | G57: 2025E | H57: 2026E | I57: 2027E | J57: 2028E
B58: Base Case | C58: 540.3 | D58: 903.6 | E58: 1386.3 | F58: 1526 | G58: 1577.2725 | H58: 1533.1089 | I58: 1379.798 | J58: 1244.9227
B59: Bull Case | C59: 540.3 | D59: 903.6 | E59: 1386.3 | F59: 1526 | G59: 1375.849 | H59: 1335.0034 | I59: 1228.2032 | J59: 1359.3261
B60: Bear Case | C60: 540.3 | D60: 903.6 | E60: 1386.3 | F60: 1526 | G60: 1531.0058 | H60: 1421.6483 | I60: 1386.1071 | J60: 963.43682
B70: Tax spent | C70: 2021A | D70: 2022A | E70: 2023A | F70: 2024A | G70: 2025E | H70: 2026E | I70: 2027E | J70: 2028E
B71: Base Case | C71: 103.5 | D71: 52.8 | E71: 60.55 | F71: 114.3 | G71: 757.0908 | H71: 1107.2453 | I71: 1724.7475 | J71: 2483.6364
B72: Bull Case | C72: 103.5 | D72: 52.8 | E72: 60.55 | F72: 114.3 | G72: 825.50938 | H72: 1068.0028 | I72: 1719.4844 | J72: 2542.3806
B73: Bear Case | C73: 103.5 | D73: 52.8 | E73: 60.55 | F73: 114.3 | G73: 492.10902 | H73: 852.98897 | I73: 1663.3285 | J73: 2522.7149

Sheet Formatting
B2: WACC | G2: Total Value | I2: % | J2: Cost
B3: MV of Debt | G3: =WACC!G21/1000000 -> 891.9 | I3: =G3/G5 -> 0.032705633 | J3: =WACC!J11 -> 0.05612979
B4: MV of Equity | G4: =WACC!G22/1000000 -> 26378.632 | I4: =G4/G5 -> 0.96729437 | J4: =WACC!J18 -> 0.121
B5: Total | G5: =SUM(G3:G4) -> 27270.532 | I5: =SUM(I3:I4) -> 1 | J5: =I3*J3+I4*J4 -> 0.11887838

Sheet Stock Data
A1: Date | B1: Price | D1: Open | E1: High | F1: Low | G1: Vol. | H1: Change % | L1: Date | M1: 45962 | N1: 45931 | O1: 45901 | P1: 45870 | Q1: 45839 | R1: 45809 | S1: 45778 | T1: 45748 | U1: 45717 | V1: 45689 | W1: 45658 | X1: 45627 | Y1: 45597 | Z1: 45566 | AA1: 45536 | AB1: 45505 | AC1: 45474 | AD1: 45444 | AE1: 45413 | AF1: 45383 | AG1: 45352 | AH1: 45323 | AI1: 45292 | AJ1: 45261 | AK1: 45231 | AL1: 45200 | AM1: 45170 | AN1: 45139 | AO1: 45108 | AP1: 45078 | AQ1: 45047 | AR1: 45017 | AS1: 44986 | AT1: 44958 | AU1: 44927 | AV1: 44896 | AW1: 44866 | AX1: 44835 | AY1: 44805 | AZ1: 44774 | BA1: 44743 | BB1: 44713 | BC1: 44682 | BD1: 44652 | BE1: 44621 | BF1: 44593 | BG1: 44562 | BH1: 44531 | BI1: 44501 | BJ1: 44470 | BK1: 44440 | BL1: 44409 | BM1: 44378 | BN1: 44348 | BO1: 44317 | BP1: 44287 | BQ1: 44256 | BR1: 44228 | BS1: 44197
A2: 45962 | B2: 245.84 | D2: 266.23 | E2: 281.5 | F2: 244.01 | G2: 31.57M | H2: -0.079 | L2: Price | M2: 245.84 | N2: 266.94 | O2: 220.53 | P2: 195.19 | Q2: 174.73 | R2: 165.54 | S2: 158.08 | T2: 125.82 | U2: 126.43 | V2: 136.18 | W2: 167.52 | X2: 176.24 | Y2: 199.27 | Z2: 194.48 | AA2: 249.44 | AB2: 227.37 | AC2: 215.99 | AD2: 225.46 | AE2: 271.76 | AF2: 176.3 | AG2: 168.8 | AH2: 153.89 | AI2: 146.3 | AJ2: 172.28 | AK2: 157.78 | AL2: 142.45 | AM2: 161.59 | AN2: 189.12 | AO2: 207.4 | AP2: 190.09 | AQ2: 202.96 | AR2: 182.58 | AS2: 217.5 | AT2: 169.14 | AU2: 177.6 | AV2: 149.79 | AW2: 172.53 | AX2: 145.57 | AY2: 132.27 | AZ2: 127.55 | BA2: 99.17 | BB2: 68.13 | BC2: 70.61 | BD2: 73.03 | BE2: 83.74 | BF2: 75.29 | BG2: 78.38 | BH2: 87.16 | BI2: 103.6 | BJ2: 119.59 | BK2: 95.46 | BL2: 94 | BM2: 86.04 | BN2: 90.51 | BO2: 76.11 | BP2: 76.53 | BQ2: 87.3 | BR2: 81.02 | BS2: 99.15
A3: 45931 | B3: 266.94 | D3: 221.78 | E3: 269.67 | F3: 216.63 | G3: 54.60M | H3: 0.2104
A4: 45901 | B4: 220.53 | D4: 190.15 | E4: 228.34 | F4: 187.64 | G4: 46.31M | H4: 0.1298
A5: 45870 | B5: 195.19 | D5: 186.34 | E5: 221.5 | F5: 176.47 | G5: 72.34M | H5: 0.1171
A6: 45839 | B6: 174.73 | D6: 165.02 | E6: 189.5 | F6: 158.81 | G6: 71.99M | H6: 0.0555
A7: 45809 | B7: 165.54 | D7: 158.21 | E7: 179.5 | F7: 135.5 | G7: 100.17M | H7: 0.0472
A8: 45778 | B8: 158.08 | D8: 127.94 | E8: 198.87 | F8: 122.47 | G8: 125.26M | H8: 0.2564
A9: 45748 | B9: 125.82 | D9: 126.11 | E9: 144.63 | F9: 116.56 | G9: 92.24M | H9: -0.0048
A10: 45717 | B10: 126.43 | D10: 135.28 | E10: 140.98 | F10: 120.6 | G10: 65.85M | H10: -0.0716
A11: 45689 | B11: 136.18 | D11: 163.31 | E11: 171.54 | F11: 133.9 | G11: 55.30M | H11: -0.1871
A12: 45658 | B12: 167.52 | D12: 177.91 | E12: 201.2 | F12: 158.08 | G12: 46.46M | H12: -0.0495
A13: 45627 | B13: 176.24 | D13: 204.35 | E13: 212.15 | F13: 173.36 | G13: 40.80M | H13: -0.1156
A14: 45597 | B14: 199.27 | D14: 195.85 | E14: 221.2 | F14: 173.37 | G14: 71.09M | H14: 0.0246
... A107: 42767 | B107: 36.19 | D107: 31.4 | E107: 38.5 | F107: 30.8 | G107: 62.06M | H107: 0.1603
